<?xml version="1.0"?>
<!-- 5-inch hull, GENERATED by Enclosure/model/gen_urdf.py and then TRIMMED for
     Gazebo. The generator does not emit usable Gazebo physics; without the four
     edits below the vehicle sinks 4.2 kg negative, is nearly immovable, is
     rolling-unstable, and produces exactly zero forward thrust.
       1. base_link <volume> 0.008157 -> 0.012338 m3  (+0.1 kg positive at 13.610 kg)
       2. <center_of_volume> -0.02525 0 0 -> -0.04928 0 0.04413  (above and in line with CG)
       3. <velocity_decay> 0.20/0.30 -> 0.006/0.02  (Gazebo applies it per STEP)
       4. rear thruster yaw -+45 deg -> +-135 deg   (else forward thrust cancels)
     Re-derive these if the hull changes; do not copy the 4-inch numbers. -->
<!-- GENERATED by gen_urdf.py - edit PARAMS there, not this file.
     Gazebo Classic 11 (ROS2 Foxy). BR 5" series, 500 mm tube.
     buoyancy + thrust are real plugins; hydrodynamics is NOT - velocity_decay
     is crude isotropic damping, not added mass or quadratic drag. -->
<robot name="hauv">
  <material name="alu"><color rgba="0.72 0.74 0.76 1.00"/></material>
  <material name="acrylic"><color rgba="0.80 0.90 1.00 0.35"/></material>
  <material name="cw_green"><color rgba="0.13 0.45 0.20 1.00"/></material>
  <material name="ccw_blue"><color rgba="0.13 0.18 0.45 1.00"/></material>
  <material name="lightblue"><color rgba="0.45 0.70 0.90 1.00"/></material>
  <material name="pcb_green"><color rgba="0.10 0.35 0.15 1.00"/></material>
  <material name="dark"><color rgba="0.20 0.20 0.22 1.00"/></material>
  <material name="grey"><color rgba="0.55 0.55 0.58 1.00"/></material>

  <link name="base_link">
    <visual><origin xyz="-0.02525 0.00000 0.00000" rpy="0.000000 1.570796 0.000000"/>
      <geometry><cylinder radius="0.06935" length="0.50000"/></geometry>
      <material name="alu"/></visual>
    <visual><origin xyz="-0.28025 0.00000 0.00000" rpy="0.000000 1.570796 0.000000"/>
      <geometry><cylinder radius="0.06650" length="0.01000"/></geometry>
      <material name="alu"/></visual>
    <visual><origin xyz="-0.26425 0.00000 0.00000" rpy="0.000000 1.570796 0.000000"/>
      <geometry><cylinder radius="0.06480" length="0.02200"/></geometry>
      <material name="alu"/></visual>
    <visual><origin xyz="0.22475 0.00000 0.00000" rpy="0.000000 0.000000 0.000000"/>
      <geometry><sphere radius="0.06050"/></geometry>
      <material name="acrylic"/></visual>
    <visual><origin xyz="-0.17000 0.00000 0.00000" rpy="0.000000 1.570796 0.000000"/>
      <geometry><cylinder radius="0.08200" length="0.01600"/></geometry>
      <material name="alu"/></visual>
    <visual><origin xyz="0.13000 0.00000 0.00000" rpy="0.000000 1.570796 0.000000"/>
      <geometry><cylinder radius="0.08200" length="0.01600"/></geometry>
      <material name="alu"/></visual>
    <visual><origin xyz="0.24100 0.14500 -0.07600" rpy="0.000000 0.000000 0.000000"/>
      <geometry><box size="0.22200 0.02000 0.01200"/></geometry>
      <material name="alu"/></visual>
    <visual><origin xyz="-0.26100 0.14500 -0.07600" rpy="0.000000 0.000000 0.000000"/>
      <geometry><box size="0.18200 0.02000 0.01200"/></geometry>
      <material name="alu"/></visual>
    <visual><origin xyz="-0.17000 0.09250 -0.07600" rpy="0.000000 0.000000 0.000000"/>
      <geometry><box size="0.01600 0.12500 0.01200"/></geometry>
      <material name="alu"/></visual>
    <visual><origin xyz="0.13000 0.09250 -0.07600" rpy="0.000000 0.000000 0.000000"/>
      <geometry><box size="0.01600 0.12500 0.01200"/></geometry>
      <material name="alu"/></visual>
    <visual><origin xyz="0.24100 -0.14500 -0.07600" rpy="0.000000 0.000000 0.000000"/>
      <geometry><box size="0.22200 0.02000 0.01200"/></geometry>
      <material name="alu"/></visual>
    <visual><origin xyz="-0.26100 -0.14500 -0.07600" rpy="0.000000 0.000000 0.000000"/>
      <geometry><box size="0.18200 0.02000 0.01200"/></geometry>
      <material name="alu"/></visual>
    <visual><origin xyz="-0.17000 -0.09250 -0.07600" rpy="0.000000 0.000000 0.000000"/>
      <geometry><box size="0.01600 0.12500 0.01200"/></geometry>
      <material name="alu"/></visual>
    <visual><origin xyz="0.13000 -0.09250 -0.07600" rpy="0.000000 0.000000 0.000000"/>
      <geometry><box size="0.01600 0.12500 0.01200"/></geometry>
      <material name="alu"/></visual>
    <visual><origin xyz="0.35200 0.00000 -0.07600" rpy="0.000000 0.000000 0.000000"/>
      <geometry><box size="0.02000 0.31000 0.01200"/></geometry>
      <material name="alu"/></visual>
    <visual><origin xyz="-0.35200 0.00000 -0.07600" rpy="0.000000 0.000000 0.000000"/>
      <geometry><box size="0.02000 0.31000 0.01200"/></geometry>
      <material name="alu"/></visual>
    <visual><origin xyz="0.04500 0.00000 0.07900" rpy="0.000000 0.000000 0.000000"/>
      <geometry><box size="0.43000 0.09000 0.01000"/></geometry>
      <material name="alu"/></visual>
    <visual><origin xyz="-0.02625 0.00000 -0.04000" rpy="0.000000 0.000000 0.000000"/>
      <geometry><box size="0.45400 0.09600 0.00400"/></geometry>
      <material name="alu"/></visual>
    <visual><origin xyz="-0.18710 0.00000 -0.00995" rpy="0.000000 0.000000 0.000000"/>
      <geometry><box size="0.11630 0.08580 0.05610"/></geometry>
      <material name="dark"/></visual>
    <visual><origin xyz="-0.06395 0.00000 -0.03200" rpy="0.000000 0.000000 0.000000"/>
      <geometry><box size="0.11000 0.07000 0.01200"/></geometry>
      <material name="pcb_green"/></visual>
    <visual><origin xyz="0.04355 0.00000 -0.02900" rpy="0.000000 0.000000 0.000000"/>
      <geometry><box size="0.08500 0.05600 0.01800"/></geometry>
      <material name="pcb_green"/></visual>
    <visual><origin xyz="0.12205 0.00000 -0.03070" rpy="0.000000 0.000000 0.000000"/>
      <geometry><box size="0.05200 0.02800 0.01460"/></geometry>
      <material name="pcb_green"/></visual>
    <visual><origin xyz="-0.15525 0.00000 0.02810" rpy="0.000000 0.000000 0.000000"/>
      <geometry><box size="0.18000 0.06500 0.02000"/></geometry>
      <material name="lightblue"/></visual>
    <visual><origin xyz="0.05225 0.00000 0.02810" rpy="0.000000 0.000000 0.000000"/>
      <geometry><box size="0.13500 0.06500 0.02000"/></geometry>
      <material name="lightblue"/></visual>
    <visual><origin xyz="-0.15525 0.00000 0.13070" rpy="0.000000 0.000000 0.000000"/>
      <geometry><cylinder radius="0.05300" length="0.09340"/></geometry>
      <material name="grey"/></visual>
    <visual><origin xyz="-0.08525 0.00000 -0.09215" rpy="0.000000 0.000000 0.000000"/>
      <geometry><cylinder radius="0.04185" length="0.04430"/></geometry>
      <material name="dark"/></visual>
    <visual><origin xyz="0.24500 0.14500 -0.11000" rpy="0.000000 1.570796 0.000000"/>
      <geometry><cylinder radius="0.01900" length="0.07800"/></geometry>
      <material name="grey"/></visual>
    <visual><origin xyz="0.24500 0.04500 0.11060" rpy="0.000000 1.570796 0.000000"/>
      <geometry><cylinder radius="0.01900" length="0.07800"/></geometry>
      <material name="grey"/></visual>
    <visual><origin xyz="0.24500 -0.14500 -0.11000" rpy="0.000000 1.570796 0.000000"/>
      <geometry><cylinder radius="0.01900" length="0.07800"/></geometry>
      <material name="grey"/></visual>
    <visual><origin xyz="0.24500 -0.04500 0.11060" rpy="0.000000 1.570796 0.000000"/>
      <geometry><cylinder radius="0.01900" length="0.07800"/></geometry>
      <material name="grey"/></visual>
    <collision><origin xyz="-0.02525 0 0" rpy="0 1.570796 0"/>
      <geometry><cylinder radius="0.06935" length="0.50000"/></geometry></collision>
    <collision><origin xyz="0 0 -0.07600" rpy="0 0 0"/>
      <geometry><box size="0.70400 0.31000 0.01200"/></geometry></collision>
    <inertial>
      <origin xyz="-0.04928 0.00000 0.01113" rpy="0 0 0"/>
      <mass value="11.546"/>
      <inertia ixx="0.097617" ixy="0.000000" ixz="0.014928" iyy="0.430519" iyz="-0.000000" izz="0.406663"/>
    </inertial>
  </link>

  <gazebo reference="base_link">
    <material>Gazebo/Grey</material>
    <velocity_decay><linear>0.006</linear><angular>0.02</angular></velocity_decay>
  </gazebo>

  <link name="t1_front_left">
    <visual><geometry><cylinder radius="0.04865" length="0.08800"/></geometry>
      <material name="cw_green"/></visual>
    <collision><geometry><cylinder radius="0.04865" length="0.08800"/></geometry></collision>
    <inertial><mass value="0.344"/>
      <inertia ixx="0.000426" ixy="0" ixz="0" iyy="0.000426" iyz="0" izz="0.000407"/></inertial>
  </link>
  <joint name="t1_front_left_joint" type="continuous">
    <parent link="base_link"/><child link="t1_front_left"/>
    <origin xyz="0.25000 0.14500 -0.02035" rpy="0.000000 1.570796 0.785398"/>
    <axis xyz="0 0 1"/>
    <dynamics damping="0.005" friction="0.0"/>
  </joint>
  <gazebo reference="t1_front_left"><material>Gazebo/Green</material></gazebo>

  <link name="t2_front_right">
    <visual><geometry><cylinder radius="0.04865" length="0.08800"/></geometry>
      <material name="ccw_blue"/></visual>
    <collision><geometry><cylinder radius="0.04865" length="0.08800"/></geometry></collision>
    <inertial><mass value="0.344"/>
      <inertia ixx="0.000426" ixy="0" ixz="0" iyy="0.000426" iyz="0" izz="0.000407"/></inertial>
  </link>
  <joint name="t2_front_right_joint" type="continuous">
    <parent link="base_link"/><child link="t2_front_right"/>
    <origin xyz="0.25000 -0.14500 -0.02035" rpy="0.000000 1.570796 -0.785398"/>
    <axis xyz="0 0 1"/>
    <dynamics damping="0.005" friction="0.0"/>
  </joint>
  <gazebo reference="t2_front_right"><material>Gazebo/Blue</material></gazebo>

  <link name="t3_rear_left">
    <visual><geometry><cylinder radius="0.04865" length="0.08800"/></geometry>
      <material name="ccw_blue"/></visual>
    <collision><geometry><cylinder radius="0.04865" length="0.08800"/></geometry></collision>
    <inertial><mass value="0.344"/>
      <inertia ixx="0.000426" ixy="0" ixz="0" iyy="0.000426" iyz="0" izz="0.000407"/></inertial>
  </link>
  <joint name="t3_rear_left_joint" type="continuous">
    <parent link="base_link"/><child link="t3_rear_left"/>
    <origin xyz="-0.25000 0.14500 -0.02035" rpy="0.000000 1.570796 2.356195"/>
    <axis xyz="0 0 1"/>
    <dynamics damping="0.005" friction="0.0"/>
  </joint>
  <gazebo reference="t3_rear_left"><material>Gazebo/Blue</material></gazebo>

  <link name="t4_rear_right">
    <visual><geometry><cylinder radius="0.04865" length="0.08800"/></geometry>
      <material name="cw_green"/></visual>
    <collision><geometry><cylinder radius="0.04865" length="0.08800"/></geometry></collision>
    <inertial><mass value="0.344"/>
      <inertia ixx="0.000426" ixy="0" ixz="0" iyy="0.000426" iyz="0" izz="0.000407"/></inertial>
  </link>
  <joint name="t4_rear_right_joint" type="continuous">
    <parent link="base_link"/><child link="t4_rear_right"/>
    <origin xyz="-0.25000 -0.14500 -0.02035" rpy="0.000000 1.570796 -2.356195"/>
    <axis xyz="0 0 1"/>
    <dynamics damping="0.005" friction="0.0"/>
  </joint>
  <gazebo reference="t4_rear_right"><material>Gazebo/Green</material></gazebo>

  <link name="t5_vert_front">
    <visual><geometry><cylinder radius="0.04865" length="0.08800"/></geometry>
      <material name="cw_green"/></visual>
    <collision><geometry><cylinder radius="0.04865" length="0.08800"/></geometry></collision>
    <inertial><mass value="0.344"/>
      <inertia ixx="0.000426" ixy="0" ixz="0" iyy="0.000426" iyz="0" izz="0.000407"/></inertial>
  </link>
  <joint name="t5_vert_front_joint" type="continuous">
    <parent link="base_link"/><child link="t5_vert_front"/>
    <origin xyz="0.35200 0.00000 -0.01220" rpy="0.000000 0.000000 0.000000"/>
    <axis xyz="0 0 1"/>
    <dynamics damping="0.005" friction="0.0"/>
  </joint>
  <gazebo reference="t5_vert_front"><material>Gazebo/Green</material></gazebo>

  <link name="t6_vert_rear">
    <visual><geometry><cylinder radius="0.04865" length="0.08800"/></geometry>
      <material name="ccw_blue"/></visual>
    <collision><geometry><cylinder radius="0.04865" length="0.08800"/></geometry></collision>
    <inertial><mass value="0.344"/>
      <inertia ixx="0.000426" ixy="0" ixz="0" iyy="0.000426" iyz="0" izz="0.000407"/></inertial>
  </link>
  <joint name="t6_vert_rear_joint" type="continuous">
    <parent link="base_link"/><child link="t6_vert_rear"/>
    <origin xyz="-0.35200 0.00000 -0.01220" rpy="0.000000 0.000000 0.000000"/>
    <axis xyz="0 0 1"/>
    <dynamics damping="0.005" friction="0.0"/>
  </joint>
  <gazebo reference="t6_vert_rear"><material>Gazebo/Blue</material></gazebo>

  <gazebo>
    <plugin name="buoyancy" filename="libBuoyancyPlugin.so">
      <fluid_density>1025</fluid_density>
      <link name="base_link">
        <center_of_volume>-0.04928 0 0.04413</center_of_volume>
        <volume>0.012338</volume>
      </link>
      <link name="t1_front_left"><center_of_volume>0 0 0</center_of_volume><volume>0.000173</volume></link>
      <link name="t2_front_right"><center_of_volume>0 0 0</center_of_volume><volume>0.000173</volume></link>
      <link name="t3_rear_left"><center_of_volume>0 0 0</center_of_volume><volume>0.000173</volume></link>
      <link name="t4_rear_right"><center_of_volume>0 0 0</center_of_volume><volume>0.000173</volume></link>
      <link name="t5_vert_front"><center_of_volume>0 0 0</center_of_volume><volume>0.000173</volume></link>
      <link name="t6_vert_rear"><center_of_volume>0 0 0</center_of_volume><volume>0.000173</volume></link>
    </plugin>
  </gazebo>

  <gazebo>
    <plugin name="t1_force" filename="libgazebo_ros_force.so">
      <ros><namespace>/hauv</namespace><remapping>gazebo_ros_force:=thruster/t1</remapping></ros>
      <link_name>t1_front_left</link_name><force_frame>link</force_frame>
    </plugin>
  </gazebo>
  <gazebo>
    <plugin name="t2_force" filename="libgazebo_ros_force.so">
      <ros><namespace>/hauv</namespace><remapping>gazebo_ros_force:=thruster/t2</remapping></ros>
      <link_name>t2_front_right</link_name><force_frame>link</force_frame>
    </plugin>
  </gazebo>
  <gazebo>
    <plugin name="t3_force" filename="libgazebo_ros_force.so">
      <ros><namespace>/hauv</namespace><remapping>gazebo_ros_force:=thruster/t3</remapping></ros>
      <link_name>t3_rear_left</link_name><force_frame>link</force_frame>
    </plugin>
  </gazebo>
  <gazebo>
    <plugin name="t4_force" filename="libgazebo_ros_force.so">
      <ros><namespace>/hauv</namespace><remapping>gazebo_ros_force:=thruster/t4</remapping></ros>
      <link_name>t4_rear_right</link_name><force_frame>link</force_frame>
    </plugin>
  </gazebo>
  <gazebo>
    <plugin name="t5_force" filename="libgazebo_ros_force.so">
      <ros><namespace>/hauv</namespace><remapping>gazebo_ros_force:=thruster/t5</remapping></ros>
      <link_name>t5_vert_front</link_name><force_frame>link</force_frame>
    </plugin>
  </gazebo>
  <gazebo>
    <plugin name="t6_force" filename="libgazebo_ros_force.so">
      <ros><namespace>/hauv</namespace><remapping>gazebo_ros_force:=thruster/t6</remapping></ros>
      <link_name>t6_vert_rear</link_name><force_frame>link</force_frame>
    </plugin>
  </gazebo>

  <link name="imu_link"/>
  <joint name="imu_joint" type="fixed">
    <parent link="base_link"/><child link="imu_link"/>
    <origin xyz="0 0 0" rpy="0 0 0"/></joint>
  <gazebo reference="imu_link">
    <sensor name="bno055" type="imu"><always_on>true</always_on>
      <update_rate>50</update_rate>
      <plugin name="imu_plugin" filename="libgazebo_ros_imu_sensor.so">
        <ros><namespace>/hauv</namespace><remapping>~/out:=imu</remapping></ros>
      </plugin></sensor></gazebo>
  <link name="camera_link"/>
  <joint name="camera_joint" type="fixed">
    <parent link="base_link"/><child link="camera_link"/>
    <origin xyz="0.22475 0 0" rpy="0 0 0"/></joint>
  <gazebo reference="camera_link">
    <sensor name="fwd_camera" type="camera"><always_on>true</always_on>
      <update_rate>15</update_rate>
      <camera><horizontal_fov>1.396</horizontal_fov>
        <image><width>640</width><height>480</height></image>
        <clip><near>0.05</near><far>30</far></clip></camera>
      <plugin name="camera_plugin" filename="libgazebo_ros_camera.so">
        <ros><namespace>/hauv</namespace></ros>
      </plugin></sensor></gazebo>
  <link name="dvl_link"/>
  <joint name="dvl_joint" type="fixed">
    <parent link="base_link"/><child link="dvl_link"/>
    <origin xyz="-0.08525 0 -0.11430" rpy="0 0 0"/></joint>
</robot>
